<?xml version="1.0"?>

<robot name="pan_tilt_camera" xmlns:xacro="http://ros.org/wiki/xacro">
  <!--<xacro:include filename="package://dynamixel_pantilt/urdf/d435.urdf.xacro"/>-->
  <xacro:include filename="d435.urdf.xacro"/>
  
  <link name="base_link">
    <visual>
      <geometry>
        <box size="0.1 0.1 0.04"/>
      </geometry>
      <material name="blue">
        <color rgba="0 0 1.0 1"/>
      </material>
    </visual>
  </link>

  <link name="pan_link">
    <visual>
      <geometry>
	<mesh filename="package://dynamixel_pantilt/meshes/ax12.stl" scale="0.001 0.001 0.001"/>

	<!-- <box size="0.04 0.03 0.05"/> -->
      </geometry>
      <material name="green">
        <color rgba="0 1.0 0 1"/>
      </material>
    </visual>
  </link>

  <link name="tilt_link">
    <visual>
      <geometry>
	<mesh filename="package://dynamixel_pantilt/meshes/ax12.stl" scale="0.001 0.001 0.001"/>

	<!-- <box size="0.04 0.03 0.05"/> -->
      </geometry>
      <material name="red">
        <color rgba="1.0 0 0 1"/>
      </material>
    </visual>
  </link>

  <link name="camera_base_link">
    <visual>
      <geometry>
        <!--<cylinder length="0.05" radius="0.02"/>-->
      </geometry>
      <material name="gray">
        <color rgba="0.5 0.5 0.5 1"/>
      </material>
    </visual>
  </link>

  <!--
  <link name="camera_link">
    <visual>
      <geometry>
        <box size="0.025 0.09 0.025"/>
      </geometry>
      <material name="gray">
        <color rgba="0.5 0.5 0.5 1"/>
      </material>
    </visual>
    </link>
  -->

  <joint name="base_to_pan" type="fixed">
    <parent link="base_link"/>
    <child link="pan_link"/>
    <origin xyz="0.0 0.0 0.04" rpy="1.5708 0 0"/>
  </joint>

  <joint name="pan_joint" type="revolute">
    <parent link="pan_link"/>
    <child link="tilt_link"/>
    <origin xyz="0.0 0.065 0.0" rpy="-1.5708 0 0"/>
    <axis xyz="0 0 1"/>
    <limit effort="1000.0" lower="-1.5" upper="1.5" velocity="0.5"/>
  </joint>

  <joint name="tilt_joint" type="revolute">
    <parent link="tilt_link"/>
    <child link="camera_base_link"/>
    <origin xyz="0.0 0.0 0.0" rpy="0 0 0"/>
    <axis xyz="0 1 0"/>
    <limit effort="1000.0" lower="-1.5" upper="1.5" velocity="0.5"/>
  </joint>

  <!--
  <joint name="camera_base_to_camera" type="fixed">
    <parent link="camera_base_link"/>
    <child link="camera_link"/>
    <origin xyz="0.0 0.0 0.035" rpy="0 0 0"/>
  </joint>
  -->

  <sensor_d435 parent="camera_base_link">
    <origin xyz="0.0 0.0 0.025" rpy="0 0 0"/>
  </sensor_d435>
  
</robot>
